<?xml version="1.0" ?>
<!-- =================================================================================== -->
<!-- |    This document was autogenerated by xacro from /home/tof/ros2_ws/src/omni_base_description/robots/omni_base.urdf.xacro | -->
<!-- |    EDITING THIS FILE BY HAND IS NOT RECOMMENDED                                 | -->
<!-- =================================================================================== -->
<!--
  Copyright (c) 2024 PAL Robotics S.L. All rights reserved.

  Licensed under the Apache License, Version 2.0 (the "License");
  you may not use this file except in compliance with the License.
  You may obtain a copy of the License at

      http://www.apache.org/licenses/LICENSE-2.0

  Unless required by applicable law or agreed to in writing, software
  distributed under the License is distributed on an "AS IS" BASIS,
  WITHOUT WARRANTIES OR CONDITIONS OF ANY KIND, either express or implied.
  See the License for the specific language governing permissions and
  limitations under the License.
-->
<robot name="omni_base">
  <!-- ARGUMENTS -->
  <!-- PROPERTIES -->
  <!-- INCLUDES -->
  <!-- PROPERTIES -->
  <material name="Blue">
    <color rgba="0.0 0.0 0.8 1.0"/>
  </material>
  <material name="Green">
    <color rgba="0.0 0.8 0.0 1.0"/>
  </material>
  <material name="Grey">
    <color rgba="0.7 0.7 0.7 1.0"/>
  </material>
  <material name="LightGrey">
    <color rgba="0.9 0.9 0.9 1.0"/>
  </material>
  <material name="DarkGrey">
    <color rgba="0.1 0.1 0.1 1.0"/>
  </material>
  <material name="Red">
    <color rgba="0.8 0.0 0.0 1.0"/>
  </material>
  <material name="White">
    <color rgba="1.0 1.0 1.0 1.0"/>
  </material>
  <material name="Yellow">
    <color rgba="0.96 0.88 0.14 1.0"/>
  </material>
  <material name="Black">
    <color rgba="0.0 0.0 0.0 1.0"/>
  </material>
  <material name="FlatBlack">
    <color rgba="0.09 0.09 0.09 1.0"/>
  </material>
  <material name="Orange">
    <color rgba="1.0 0.487 0.0 1.0"/>
  </material>
  <material name="pal/Orange">
    <color rgba="0.91373 0.61568 0.29411 1.0"/>
  </material>
  <material name="pal/DarkGrey">
    <color rgba="0.29804 0.29804 0.29804 1"/>
  </material>
  <!-- ROS 2 control config-->
  <ros2_control name="ros2_control_omni_base_system" type="system">
    <!-- HW interface; robot control-->
    <hardware>
      <plugin>gz_ros2_control/GazeboSimSystem</plugin>
    </hardware>
    <joint name="wheel_front_right_joint">
      <command_interface name="velocity">
        <param name="min">-1</param>
        <param name="max">1</param>
      </command_interface>
      <state_interface name="position"/>
      <state_interface name="velocity"/>
    </joint>
    <transmission name="wheel_front_right_trans">
      <plugin>transmission_interface/SimpleTransmission</plugin>
      <actuator name="wheel_front_right_actuator" role="actuator1"/>
      <joint name="wheel_front_right_joint" role="joint1">
        <mechanical_reduction>1.0</mechanical_reduction>
      </joint>
    </transmission>
    <joint name="wheel_front_left_joint">
      <command_interface name="velocity">
        <param name="min">-1</param>
        <param name="max">1</param>
      </command_interface>
      <state_interface name="position"/>
      <state_interface name="velocity"/>
    </joint>
    <transmission name="wheel_front_left_trans">
      <plugin>transmission_interface/SimpleTransmission</plugin>
      <actuator name="wheel_front_left_actuator" role="actuator1"/>
      <joint name="wheel_front_left_joint" role="joint1">
        <mechanical_reduction>1.0</mechanical_reduction>
      </joint>
    </transmission>
    <joint name="wheel_rear_right_joint">
      <command_interface name="velocity">
        <param name="min">-1</param>
        <param name="max">1</param>
      </command_interface>
      <state_interface name="position"/>
      <state_interface name="velocity"/>
    </joint>
    <transmission name="wheel_rear_right_trans">
      <plugin>transmission_interface/SimpleTransmission</plugin>
      <actuator name="wheel_rear_right_actuator" role="actuator1"/>
      <joint name="wheel_rear_right_joint" role="joint1">
        <mechanical_reduction>1.0</mechanical_reduction>
      </joint>
    </transmission>
    <joint name="wheel_rear_left_joint">
      <command_interface name="velocity">
        <param name="min">-1</param>
        <param name="max">1</param>
      </command_interface>
      <state_interface name="position"/>
      <state_interface name="velocity"/>
    </joint>
    <transmission name="wheel_rear_left_trans">
      <plugin>transmission_interface/SimpleTransmission</plugin>
      <actuator name="wheel_rear_left_actuator" role="actuator1"/>
      <joint name="wheel_rear_left_joint" role="joint1">
        <mechanical_reduction>1.0</mechanical_reduction>
      </joint>
    </transmission>
  </ros2_control>
  <!-- ROBOT DEFINITION -->
  <link name="base_rear_laser_link" type="laser">
    <inertial>
      <origin rpy="0 0 0" xyz="-0.02559000000 -0.00056000000 -0.05732000000"/>
      <mass value="0.28922000000"/>
      <inertia ixx="0.00002628919" ixy="0.00000024298" ixz="-0.00000368129" iyy="0.00003374542" iyz="-0.00000001330" izz="0.00005832599"/>
    </inertial>
    <visual>
      <origin rpy="0 0 0" xyz="0 0 0"/>
      <geometry>
        <mesh filename="package://robot_omni/meshes/sensors/sick_tim551.stl" scale="1 1 1"/>
      </geometry>
      <material name="DarkGrey"/>
    </visual>
    <collision>
      <origin rpy="0 0 0" xyz="0 0 0"/>
      <geometry>
        <cylinder length="0.01" radius="0.01"/>
      </geometry>
    </collision>
  </link>
  <joint name="base_rear_laser_joint" type="fixed">
    <axis xyz="0 1 0"/>
    <origin rpy="-3.141592653589793 0 2.356194490192345" xyz="-0.27512 0.18297 0.13244"/>
    <parent link="base_link"/>
    <child link="base_rear_laser_link"/>
  </joint>
  <gazebo reference="base_rear_laser_link">
    <sensor name="base_rear_laser" type="gpu_lidar">
      <pose>0 0 0 0 0 0</pose>
      <update_rate>10</update_rate>
      <visualize>true</visualize>
      <topic>scan_rear_raw</topic>
      <gz_frame_id>base_rear_laser_link</gz_frame_id>
      <ray>
        <scan>
          <horizontal>
            <!-- 818 (270/0.33) steps in 270deg fov -->
            <samples>818.0</samples>
            <resolution>1</resolution>
            <!-- not the sensor resolution; just 1 -->
            <min_angle>-2.356194490192345</min_angle>
            <max_angle>2.356194490192345</max_angle>
          </horizontal>
        </scan>
        <range>
          <min>0.05</min>
          <max>25.0</max>
          <resolution>0.001</resolution>
        </range>
        <noise>
          <type>gaussian</type>
          <mean>0.0</mean>
          <stddev>0.01</stddev>
        </noise>
      </ray>
    </sensor>
    <material>Gazebo/DarkGrey</material>
  </gazebo>
  <link name="base_front_laser_link" type="laser">
    <inertial>
      <origin rpy="0 0 0" xyz="-0.02559000000 -0.00056000000 -0.05732000000"/>
      <mass value="0.28922000000"/>
      <inertia ixx="0.00002628919" ixy="0.00000024298" ixz="-0.00000368129" iyy="0.00003374542" iyz="-0.00000001330" izz="0.00005832599"/>
    </inertial>
    <visual>
      <origin rpy="0 0 0" xyz="0 0 0"/>
      <geometry>
        <mesh filename="package://robot_omni/meshes/sensors/sick_tim551.stl" scale="1 1 1"/>
      </geometry>
      <material name="DarkGrey"/>
    </visual>
    <collision>
      <origin rpy="0 0 0" xyz="0 0 0"/>
      <geometry>
        <cylinder length="0.01" radius="0.01"/>
      </geometry>
    </collision>
  </link>
  <joint name="base_front_laser_joint" type="fixed">
    <axis xyz="0 1 0"/>
    <origin rpy="-3.141592653589793 0 -0.7853981633974483" xyz="0.27512 -0.18297 0.13244"/>
    <parent link="base_link"/>
    <child link="base_front_laser_link"/>
  </joint>
  <gazebo reference="base_front_laser_link">
    <sensor name="base_front_laser" type="gpu_lidar">
      <pose>0 0 0 0 0 0</pose>
      <update_rate>10</update_rate>
      <visualize>true</visualize>
      <topic>scan_front_raw</topic>
      <gz_frame_id>base_front_laser_link</gz_frame_id>
      <ray>
        <scan>
          <horizontal>
            <!-- 818 (270/0.33) steps in 270deg fov -->
            <samples>818.0</samples>
            <resolution>1</resolution>
            <!-- not the sensor resolution; just 1 -->
            <min_angle>-2.356194490192345</min_angle>
            <max_angle>2.356194490192345</max_angle>
          </horizontal>
        </scan>
        <range>
          <min>0.05</min>
          <max>25.0</max>
          <resolution>0.001</resolution>
        </range>
        <noise>
          <type>gaussian</type>
          <mean>0.0</mean>
          <stddev>0.01</stddev>
        </noise>
      </ray>
    </sensor>
    <material>Gazebo/DarkGrey</material>
  </gazebo>
  <!-- Virtual Base Laser Link -->
  <joint name="virtual_base_laser_joint" type="fixed">
    <parent link="base_link"/>
    <child link="virtual_base_laser_link"/>
    <origin rpy="0 0 0" xyz="0 0 0.13244"/>
  </joint>
  <link name="virtual_base_laser_link">
    <inertial>
      <origin rpy="0 0 0" xyz="0 0 0"/>
      <mass value="0.0001"/>
      <inertia ixx="0.0001" ixy="0" ixz="0" iyy="0.0001" iyz="0" izz="0.0001"/>
    </inertial>
  </link>
  <link name="base_imu_link">
    <inertial>
      <mass value="0.01"/>
      <origin xyz="0 0 0"/>
      <inertia ixx="0.000001" ixy="0" ixz="0" iyy="0.000001" iyz="0" izz="0.000001"/>
    </inertial>
  </link>
  <joint name="base_imu_joint" type="fixed">
    <parent link="base_link"/>
    <child link="base_imu_link"/>
    <origin rpy="0 0 1.5707963267948966" xyz="-0.287 0 0.092163"/>
  </joint>
  <gazebo reference="base_imu_link">
    <sensor name="base_imu_sensor" type="imu">
      <always_on>1</always_on>
      <update_rate>100.0</update_rate>
      <visualize>true</visualize>
      <topic>base_imu</topic>
    </sensor>
  </gazebo>
  <!-- Base -->
  <link name="base_link">
    <inertial>
      <origin rpy="0 0 0" xyz="0.0026742 0.00027459 0.086363"/>
      <mass value="34.047"/>
      <inertia ixx="0.22777" ixy="0.00035979" ixz="0.00015269" iyy="0.29991" iyz="1.7872E-05" izz="0.46036"/>
    </inertial>
    <visual>
      <origin rpy="0 0 0" xyz="0 0 0"/>
      <geometry>
        <mesh filename="package://robot_omni/meshes/base/base_link.stl"/>
      </geometry>
      <material name="">
        <color rgba="0.75294 0.75294 0.75294 1"/>
      </material>
    </visual>
    <collision>
      <origin rpy="0 0 0" xyz="0 0 0.18925"/>
      <geometry>
        <box size="0.717 0.497 0.0845"/>
      </geometry>
    </collision>
    <collision>
      <origin rpy="0 0 0" xyz="0 0 0.132"/>
      <geometry>
        <box size="0.58 0.39 0.03"/>
      </geometry>
    </collision>
    <collision>
      <origin rpy="0 0 0" xyz="0 0 0.0335"/>
      <geometry>
        <box size="0.705 0.48 0.167"/>
      </geometry>
    </collision>
  </link>
  <!-- Base footprint -->
  <link name="base_footprint"/>
  <joint name="base_footprint_joint" type="fixed">
    <origin rpy="0 0 0" xyz="0 0 0"/>
    <child link="base_link"/>
    <parent link="base_footprint"/>
  </joint>
  <!-- Docking link -->
  <link name="base_dock_link">
    <inertial>
      <origin rpy="0 0 0" xyz="-0.0037082 1.5226E-18 -4.1633E-17"/>
      <mass value="0.032242"/>
      <inertia ixx="2.1302E-05" ixy="-1.0461E-21" ixz="6.6555E-22" iyy="1.2058E-05" iyz="-1.9453E-21" izz="1.0058E-05"/>
    </inertial>
    <visual>
      <origin rpy="0 0 0" xyz="0 0 0"/>
      <geometry>
        <mesh filename="package://robot_omni/meshes/base/base_dock_link.stl"/>
      </geometry>
      <material name="">
        <color rgba="0.25098 0.25098 0.25098 1"/>
      </material>
    </visual>
    <collision>
      <origin rpy="0 0 0" xyz="0 0 0"/>
      <geometry>
        <mesh filename="package://robot_omni/meshes/base/base_dock_link.stl"/>
      </geometry>
    </collision>
  </link>
  <joint name="base_dock" type="fixed">
    <origin rpy="0 0 0" xyz="0.3535 0 0.0596"/>
    <parent link="base_link"/>
    <child link="base_dock_link"/>
    <axis xyz="0 0 0"/>
  </joint>
  <link name="base_antenna_right_link">
    <inertial>
      <origin rpy="0 0 0" xyz="0.027807 -0.0085125 0.015138"/>
      <mass value="0.02311"/>
      <inertia ixx="2.3107E-06" ixy="5.0914e-06" ixz="8.5605E-08" iyy="1.7384E-05" iyz="-2.6206e-08" izz="1.8542E-05"/>
    </inertial>
    <visual>
      <origin rpy="0 0 0" xyz="0 0 0"/>
      <geometry>
        <mesh filename="package://robot_omni/meshes/base/base_antena_link.stl" scale="1 1 1"/>
      </geometry>
      <material name="">
        <color rgba="0.75294 0.75294 0.75294 1"/>
      </material>
    </visual>
    <collision>
      <origin rpy="0 0 0" xyz="0 0 0"/>
      <geometry>
        <mesh filename="package://robot_omni/meshes/base/base_antena_link.stl" scale="1 1 1"/>
      </geometry>
    </collision>
  </link>
  <joint name="base_antenna_right_joint" type="fixed">
    <origin rpy="0 0 0" xyz="-0.2015 -0.13 0.2165"/>
    <parent link="base_link"/>
    <child link="base_antenna_right_link"/>
    <axis xyz="0 0 0"/>
  </joint>
  <gazebo reference="base_antenna_right_link">
    <material>Gazebo/Black</material>
  </gazebo>
  <link name="base_antenna_left_link">
    <inertial>
      <origin rpy="0 0 0" xyz="0.027807 0.0085125 0.015138"/>
      <mass value="0.02311"/>
      <inertia ixx="2.3107E-06" ixy="-5.0914e-06" ixz="8.5605E-08" iyy="1.7384E-05" iyz="2.6206e-08" izz="1.8542E-05"/>
    </inertial>
    <visual>
      <origin rpy="0 0 0" xyz="0 0 0"/>
      <geometry>
        <mesh filename="package://robot_omni/meshes/base/base_antena_link.stl" scale="1 -1 1"/>
      </geometry>
      <material name="">
        <color rgba="0.75294 0.75294 0.75294 1"/>
      </material>
    </visual>
    <collision>
      <origin rpy="0 0 0" xyz="0 0 0"/>
      <geometry>
        <mesh filename="package://robot_omni/meshes/base/base_antena_link.stl" scale="1 -1 1"/>
      </geometry>
    </collision>
  </link>
  <joint name="base_antenna_left_joint" type="fixed">
    <origin rpy="0 0 0" xyz="-0.2015 0.13 0.2165"/>
    <parent link="base_link"/>
    <child link="base_antenna_left_link"/>
    <axis xyz="0 0 0"/>
  </joint>
  <gazebo reference="base_antenna_left_link">
    <material>Gazebo/Black</material>
  </gazebo>
  <link name="suspension_front_right_link">
    <inertial>
      <origin rpy="0 0 0" xyz="-0.058182 -0.0043908 -0.0057695"/>
      <mass value="1.2879"/>
      <inertia ixx="0.0015947" ixy="-0.00013183" ixz="1.7315E-05" iyy="0.00060158" iyz="-6.0731e-05" izz="0.0015861"/>
    </inertial>
    <visual>
      <origin rpy="0 0 0" xyz="0 0 0"/>
      <geometry>
        <mesh filename="package://robot_omni/meshes/wheels/suspension_front_link.stl" scale="1 1.0 1"/>
      </geometry>
      <material name="">
        <color rgba="0.79216 0.81961 0.93333 1"/>
      </material>
    </visual>
    <collision>
      <origin rpy="0 0 0" xyz="0 0 0"/>
      <geometry>
        <mesh filename="package://robot_omni/meshes/wheels/suspension_front_link.stl" scale="1 1.0 1"/>
      </geometry>
    </collision>
    <kinematic>0</kinematic>
    <gravity>1</gravity>
  </link>
  <!-- Changed joint type to fixed joint. It is observed that the robot is loosing contact points due to some issues with the Gazebo Physics Engine. This makes the robot drift in localization when static due to added noise -->
  <joint name="suspension_front_right_joint" type="fixed">
    <origin rpy="0 0 -1.5707963267948966" xyz="0.244 -0.1725 0"/>
    <parent link="base_link"/>
    <child link="suspension_front_right_link"/>
    <axis xyz="0 0 1"/>
  </joint>
  <link name="wheel_front_right_link">
    <inertial>
      <origin rpy="0 0 0" xyz="5.4922e-09 6.9775e-05 0.011144"/>
      <mass value="0.70767"/>
      <inertia ixx="0.00035492" ixy="7.5685e-13" ixz="3.8795E-11" iyy="0.00035529" iyz="-2.0284e-07" izz="0.00040131"/>
    </inertial>
    <visual>
      <origin rpy="0 0 0" xyz="0 0 0"/>
      <geometry>
        <mesh filename="package://robot_omni/meshes/wheels/wheel_link.stl" scale="1 1 1.0"/>
      </geometry>
      <material name="DarkGrey"/>
    </visual>
    <collision>
      <origin rpy="0 0 0" xyz="0 0 0"/>
      <geometry>
        <cylinder length="0.05" radius="0.0762"/>
      </geometry>
    </collision>
  </link>
  <joint name="wheel_front_right_joint" type="continuous">
    <origin rpy="-1.5707963267948966 0 1.5707963267948966" xyz="0.050675 0 0"/>
    <parent link="suspension_front_right_link"/>
    <child link="wheel_front_right_link"/>
    <axis xyz="0 0 1"/>
    <limit effort="6.0" velocity="13.123359580052492"/>
    <dynamics damping="1.0" friction="2.0"/>
  </joint>
  <!-- Contact model for the wheel surface -->
  <gazebo reference="wheel_front_right_link">
    <kp>1000000.0</kp>
    <kd>1000.0</kd>
    <mu1>1.0</mu1>
    <mu2>0.1</mu2>
    <fdir1>1 0 0</fdir1>
    <maxVel>1.0</maxVel>
    <minDepth>0.00</minDepth>
    <implicitSpringDamper>1</implicitSpringDamper>
    <material>Gazebo/Grey</material>
  </gazebo>
  <link name="suspension_front_left_link">
    <inertial>
      <origin rpy="0 0 0" xyz="-0.058182 0.0043908 -0.0057695"/>
      <mass value="1.2879"/>
      <inertia ixx="0.0015947" ixy="0.00013183" ixz="1.7315E-05" iyy="0.00060158" iyz="6.0731e-05" izz="0.0015861"/>
    </inertial>
    <visual>
      <origin rpy="0 0 0" xyz="0 0 0"/>
      <geometry>
        <mesh filename="package://robot_omni/meshes/wheels/suspension_front_link.stl" scale="1 -1.0 1"/>
      </geometry>
      <material name="">
        <color rgba="0.79216 0.81961 0.93333 1"/>
      </material>
    </visual>
    <collision>
      <origin rpy="0 0 0" xyz="0 0 0"/>
      <geometry>
        <mesh filename="package://robot_omni/meshes/wheels/suspension_front_link.stl" scale="1 -1.0 1"/>
      </geometry>
    </collision>
    <kinematic>0</kinematic>
    <gravity>1</gravity>
  </link>
  <!-- Changed joint type to fixed joint. It is observed that the robot is loosing contact points due to some issues with the Gazebo Physics Engine. This makes the robot drift in localization when static due to added noise -->
  <joint name="suspension_front_left_joint" type="fixed">
    <origin rpy="0 0 1.5707963267948966" xyz="0.244 0.1725 0"/>
    <parent link="base_link"/>
    <child link="suspension_front_left_link"/>
    <axis xyz="0 0 1"/>
  </joint>
  <link name="wheel_front_left_link">
    <inertial>
      <origin rpy="0 0 0" xyz="5.4922e-09 -6.9775e-05 -0.011144"/>
      <mass value="0.70767"/>
      <inertia ixx="0.00035492" ixy="7.5685e-13" ixz="3.8795E-11" iyy="0.00035529" iyz="-2.0284e-07" izz="0.00040131"/>
    </inertial>
    <visual>
      <origin rpy="0 0 0" xyz="0 0 0"/>
      <geometry>
        <mesh filename="package://robot_omni/meshes/wheels/wheel_link.stl" scale="1 1 -1.0"/>
      </geometry>
      <material name="DarkGrey"/>
    </visual>
    <collision>
      <origin rpy="0 0 0" xyz="0 0 0"/>
      <geometry>
        <cylinder length="0.05" radius="0.0762"/>
      </geometry>
    </collision>
  </link>
  <joint name="wheel_front_left_joint" type="continuous">
    <origin rpy="-1.5707963267948966 0 -1.5707963267948966" xyz="0.050675 0 0"/>
    <parent link="suspension_front_left_link"/>
    <child link="wheel_front_left_link"/>
    <axis xyz="0 0 1"/>
    <limit effort="6.0" velocity="13.123359580052492"/>
    <dynamics damping="1.0" friction="2.0"/>
  </joint>
  <!-- Contact model for the wheel surface -->
  <gazebo reference="wheel_front_left_link">
    <kp>1000000.0</kp>
    <kd>1000.0</kd>
    <mu1>1.0</mu1>
    <mu2>0.1</mu2>
    <fdir1>1 0 0</fdir1>
    <maxVel>1.0</maxVel>
    <minDepth>0.00</minDepth>
    <implicitSpringDamper>1</implicitSpringDamper>
    <material>Gazebo/Grey</material>
  </gazebo>
  <link name="suspension_rear_right_link">
    <inertial>
      <origin rpy="0 0 0" xyz="-0.058182 0.0043908 -0.0057695"/>
      <mass value="1.2879"/>
      <inertia ixx="0.0015947" ixy="0.00013183" ixz="1.7315E-05" iyy="0.00060158" iyz="6.0731e-05" izz="0.0015861"/>
    </inertial>
    <visual>
      <origin rpy="0 0 0" xyz="0 0 0"/>
      <geometry>
        <mesh filename="package://robot_omni/meshes/wheels/suspension_rear_link.stl" scale="1 1.0 1"/>
      </geometry>
      <material name="">
        <color rgba="0.79216 0.81961 0.93333 1"/>
      </material>
    </visual>
    <collision>
      <origin rpy="0 0 0" xyz="0 0 0"/>
      <geometry>
        <mesh filename="package://robot_omni/meshes/wheels/suspension_rear_link.stl" scale="1 1.0 1"/>
      </geometry>
    </collision>
    <kinematic>0</kinematic>
    <gravity>1</gravity>
  </link>
  <!-- Changed joint type to fixed joint. It is observed that the robot is loosing contact points due to some issues with the Gazebo Physics Engine. This makes the robot drift in localization when static due to added noise -->
  <joint name="suspension_rear_right_joint" type="fixed">
    <origin rpy="0 0 -1.5707963267948966" xyz="-0.244 -0.1725 0"/>
    <parent link="base_link"/>
    <child link="suspension_rear_right_link"/>
    <axis xyz="0 0 1"/>
  </joint>
  <link name="wheel_rear_right_link">
    <inertial>
      <origin rpy="0 0 0" xyz="-5.4922e-09 -6.9775e-05 0.011144"/>
      <mass value="0.70767"/>
      <inertia ixx="0.00035492" ixy="-7.5685e-13" ixz="3.8795E-11" iyy="0.00035529" iyz="2.0284e-07" izz="0.00040131"/>
    </inertial>
    <visual>
      <origin rpy="0 0 0" xyz="0 0 0"/>
      <geometry>
        <mesh filename="package://robot_omni/meshes/wheels/wheel_link.stl" scale="1 1 1.0"/>
      </geometry>
      <material name="DarkGrey"/>
    </visual>
    <collision>
      <origin rpy="0 0 0" xyz="0 0 0"/>
      <geometry>
        <cylinder length="0.05" radius="0.0762"/>
      </geometry>
    </collision>
  </link>
  <joint name="wheel_rear_right_joint" type="continuous">
    <origin rpy="-1.5707963267948966 0 1.5707963267948966" xyz="0.050675 0 0"/>
    <parent link="suspension_rear_right_link"/>
    <child link="wheel_rear_right_link"/>
    <axis xyz="0 0 1"/>
    <limit effort="6.0" velocity="13.123359580052492"/>
    <dynamics damping="1.0" friction="2.0"/>
  </joint>
  <!-- Contact model for the wheel surface -->
  <gazebo reference="wheel_rear_right_link">
    <kp>1000000.0</kp>
    <kd>1000.0</kd>
    <mu1>1.0</mu1>
    <mu2>0.1</mu2>
    <fdir1>1 0 0</fdir1>
    <maxVel>1.0</maxVel>
    <minDepth>0.00</minDepth>
    <implicitSpringDamper>1</implicitSpringDamper>
    <material>Gazebo/Grey</material>
  </gazebo>
  <link name="suspension_rear_left_link">
    <inertial>
      <origin rpy="0 0 0" xyz="-0.058182 -0.0043908 -0.0057695"/>
      <mass value="1.2879"/>
      <inertia ixx="0.0015947" ixy="-0.00013183" ixz="1.7315E-05" iyy="0.00060158" iyz="-6.0731e-05" izz="0.0015861"/>
    </inertial>
    <visual>
      <origin rpy="0 0 0" xyz="0 0 0"/>
      <geometry>
        <mesh filename="package://robot_omni/meshes/wheels/suspension_rear_link.stl" scale="1 -1.0 1"/>
      </geometry>
      <material name="">
        <color rgba="0.79216 0.81961 0.93333 1"/>
      </material>
    </visual>
    <collision>
      <origin rpy="0 0 0" xyz="0 0 0"/>
      <geometry>
        <mesh filename="package://robot_omni/meshes/wheels/suspension_rear_link.stl" scale="1 -1.0 1"/>
      </geometry>
    </collision>
    <kinematic>0</kinematic>
    <gravity>1</gravity>
  </link>
  <!-- Changed joint type to fixed joint. It is observed that the robot is loosing contact points due to some issues with the Gazebo Physics Engine. This makes the robot drift in localization when static due to added noise -->
  <joint name="suspension_rear_left_joint" type="fixed">
    <origin rpy="0 0 1.5707963267948966" xyz="-0.244 0.1725 0"/>
    <parent link="base_link"/>
    <child link="suspension_rear_left_link"/>
    <axis xyz="0 0 1"/>
  </joint>
  <link name="wheel_rear_left_link">
    <inertial>
      <origin rpy="0 0 0" xyz="-5.4922e-09 6.9775e-05 -0.011144"/>
      <mass value="0.70767"/>
      <inertia ixx="0.00035492" ixy="-7.5685e-13" ixz="3.8795E-11" iyy="0.00035529" iyz="2.0284e-07" izz="0.00040131"/>
    </inertial>
    <visual>
      <origin rpy="0 0 0" xyz="0 0 0"/>
      <geometry>
        <mesh filename="package://robot_omni/meshes/wheels/wheel_link.stl" scale="1 1 -1.0"/>
      </geometry>
      <material name="DarkGrey"/>
    </visual>
    <collision>
      <origin rpy="0 0 0" xyz="0 0 0"/>
      <geometry>
        <cylinder length="0.05" radius="0.0762"/>
      </geometry>
    </collision>
  </link>
  <joint name="wheel_rear_left_joint" type="continuous">
    <origin rpy="-1.5707963267948966 0 -1.5707963267948966" xyz="0.050675 0 0"/>
    <parent link="suspension_rear_left_link"/>
    <child link="wheel_rear_left_link"/>
    <axis xyz="0 0 1"/>
    <limit effort="6.0" velocity="13.123359580052492"/>
    <dynamics damping="1.0" friction="2.0"/>
  </joint>
  <!-- Contact model for the wheel surface -->
  <gazebo reference="wheel_rear_left_link">
    <kp>1000000.0</kp>
    <kd>1000.0</kd>
    <mu1>1.0</mu1>
    <mu2>0.1</mu2>
    <fdir1>1 0 0</fdir1>
    <maxVel>1.0</maxVel>
    <minDepth>0.00</minDepth>
    <implicitSpringDamper>1</implicitSpringDamper>
    <material>Gazebo/Grey</material>
  </gazebo>
  <!-- Materials -->
  <gazebo reference="base_link">
    <material>Gazebo/White</material>
  </gazebo>
  <!-- base_link through base_footprint-->
  <gazebo reference="base_footprint">
    <kp>100000000.0</kp>
    <kd>10.0</kd>
    <mu1>0.1</mu1>
    <mu2>0.1</mu2>
    <fdir1>1 0 0</fdir1>
    <maxVel>10.0</maxVel>
    <minDepth>0.0005</minDepth>
    <laserRetro>0</laserRetro>
  </gazebo>

  <gazebo>
  <plugin filename="libgz_ros2_control-system.so"
          name="gz_ros2_control::GazeboSimROS2ControlPlugin">
    <parameters>/home/alberthtran/ros2_project/install/robot_omni/share/robot_omni/config/configuration.yaml</parameters>
  </plugin>
  <plugin
    filename="gz-sim-imu-system"
    name="gz::sim::systems::Imu">
  </plugin>

</gazebo>


</robot>
